Workbook

Sheet Sheet3
A1: Validation_Requried | B1: Y
A3: Count of PoC (TrnDtl) | C3: Source | M3: Consist | N3: Equipment | O3: Location | P3: Mechanical | Q3: Miles | R3: Time | S3: TonneMiles | T3: Train | U3: Waybill | V3: Weight
A4: Table | B4: Dimension | C4: BMR | D4: BrandNew | E4: TrnCnstDtl | F4: TrnLvlSmry | G4: Grand Total | L4: Validity | O4: Y | P4: Y | T4: Y | U4: Y | V4: Y
A5: Train_Detail | B5: Consist | D5: 1 | E5: 1 | F5: 1 | G5: 3 | L5: Completeness | O5: Y
B6: Equipment | D6: 13 | E6: 5 | G6: 18 | L6: Consistency | M6: Y
B7: Location | C7: 6 | D7: 8 | F7: 6 | G7: 20 | L7: Integrity | O7: Y | S7: Y
B8: Mechanical | F8: 1 | G8: 1 | L8: Timeliness | R8: Y | S8: Y
B9: Miles | F9: 9 | G9: 9 | L9: Currency | O9: Y | R9: Y | S9: Y
B10: Time | D10: 1 | E10: 1 | F10: 5 | G10: 7 | L10: Reasonableness | N10: Y | P10: Y
B11: TonneMiles | F11: 3 | G11: 3 | L11: Uniqueness | M11: Y
B12: Train | D12: 3 | G12: 3 | L12: Accuracy | M12: Y | O12: Y | Q12: Y | S12: Y | V12: Y
B13: Waybill | D13: 9 | E13: 13 | G13: 22
B14: Weight | F14: 2 | G14: 2
A15: Train_Detail Total | C15: 6 | D15: 35 | E15: 20 | F15: 27 | G15: 88
A16: Train_Summary | B16: Consist | D16: 1 | F16: 4 | G16: 5
B17: Equipment | D17: 1 | F17: 3 | G17: 4
B18: Location | C18: 6 | D18: 8 | F18: 6 | G18: 20
B19: Mechanical | F19: 1 | G19: 1
B20: Miles | C20: 2 | F20: 9 | G20: 11
B21: Time | D21: 1 | F21: 5 | G21: 6
B22: TonneMiles | F22: 2 | G22: 2
B23: Train | D23: 2 | G23: 2
B24: Weight | F24: 2 | G24: 2
A25: Train_Summary Total | C25: 8 | D25: 13 | F25: 32 | G25: 53
A26: Grand Total | C26: 14 | D26: 48 | E26: 20 | F26: 59 | G26: 141
A30: Validation_Requried | B30: Y
A32: Dimension | B32: Count of PoC (TrnDtl) | M32: Validity | N32: Completeness | O32: Consistency | P32: Integrity | Q32: Timeliness | R32: Currency | S32: Reasonableness | T32: Uniqueness | U32: Accuracy
A33: Consist | B33: 8 | L33: Consist | O33: Y | T33: Y | U33: Y
A34: Equipment | B34: 22 | L34: Equipment | S34: Y
A35: Location | B35: 40 | L35: Location | M35: Y | N35: Y | P35: Y | R35: Y | U35: Y
A36: Mechanical | B36: 2 | L36: Mechanical | M36: Y | S36: Y
A37: Miles | B37: 20 | L37: Miles | U37: Y
A38: Time | B38: 13 | L38: Time | Q38: Y | R38: Y
A39: TonneMiles | B39: 5 | L39: TonneMiles | P39: Y | Q39: Y | R39: Y | U39: Y
A40: Train | B40: 5 | L40: Train | M40: Y
A41: Waybill | B41: 22 | L41: Waybill | M41: Y
A42: Weight | B42: 4 | L42: Weight | M42: Y | U42: Y
A43: Grand Total | B43: 141
A51: Validation_Requried | B51: Y
A53: Count of PoC (TrnDtl) | C53: Source
...

Sheet Proposed Data Tables (2 tables)
A1: Table | B1: SEQ | C1: Code | D1: Source | E1: Validation_Priority | F1: Validation_Requried | G1: PoC (TrnDtl) | H1: Dimension | I1: Field_Type | J1: Field_Name | K1: Validation_Logic_Approach | L1: Data Dictionary | M1: Example or Methodology | N1: Active Data? (Y/N) | O1: Source Schema.Table.Column Name // Vicky's Comments | P1: Future Sources | Q1: Transformations / Validation / If/else | R1: ExpectedResult | S1: Count of NULl | T1: Count of TTL Rows | U1: % of NULL
A2: Train_Detail | B2: 1 | C2: Train142 | D2: BrandNew | E2: LOW | F2: N | G2: Y | H2: Time | J2: Train Year | L2: Calendar year of the actual departure from origin for this train instance. | M2: 2025 | N2: Y | O2: eqpmv.eqpmv_rfeqp_mvmnt_event.report_tms | Q2: Y | R2: N/A
A3: Train_Detail | B3: 2 | C3: Train143 | D3: BrandNew | E3: LOW | F3: N | G3: Y | H3: Time | J3: Train Quarter | L3: Quarter that a train departed from its origin | M3: 1 | N3: Y | O3: eqpmv.eqpmv_rfeqp_mvmnt_event.report_tms | Q3: Y | R3: N/A
A4: Train_Detail | B4: 3 | C4: Train144 | D4: BrandNew | E4: LOW | F4: N | G4: Y | H4: Time | J4: Train Month | L4: Month that a train departed from its origin | M4: 2 | N4: Y | O4: eqpmv.eqpmv_rfeqp_mvmnt_event.report_tms | Q4: Y | R4: N/A
A5: Train_Detail | B5: 4 | C5: Train145 | D5: BrandNew | E5: LOW | F5: N | G5: Y | H5: Time | J5: Train Day | L5: Day that a train departed from its origin | M5: 25 | N5: Y | O5: eqpmv.eqpmv_rfeqp_mvmnt_event.report_tms | Q5: Y | R5: N/A
A6: Train_Detail | B6: 5 | C6: Train009 | D6: TrnLvlSmry | E6: HIGH | F6: Y | G6: Y | H6: Time | J6: SADB_RECEIVING_DT | K6: Data Freshnesss: SADB_RECEIVING_DT = ARRIVE_TMS BY DATE | L6: Reporting time stamp for most recent events at the time train was reported | M6: 8/2/25 0:00 | N6: Y | O6: eqpmv.eqpmv_rfeqp_mvmnt_event lcmtv.lcmtv_mvmnt_event | Q6: N | R6: 1
A7: Train_Detail | B7: 6 | C7: Train001 | D7: TrnLvlSmry | E7: MEDIUM | F7: N | G7: Y | H7: System | J7: SRC_SYS | L7: Source systems such as KCS = MCS or CP = TYES | M7: KCS | N7: Y | O7: Exact Source not identified yet | Q7: N | R7: 1
A8: Train_Detail | B8: 7 | C8: Train048 | D8: TrnLvlSmry | E8: MEDIUM | F8: N | G8: Y | H8: Train | J8: TRAIN_SERIES | L8: Train series identifier | M8: 100 | N8: Y | O8: Derived from Train_Name | Q8: Y
A9: Train_Detail | B9: 8 | C9: Train050 | D9: TrnLvlSmry | E9: MEDIUM | F9: N | G9: Y | H9: Train | J9: TRAIN_SYMBOL | L9: Train symbol code | M9: 181 | N9: Y | O9: Derived from Train_Name | Q9: Y
A10: Train_Detail | B10: 9 | C10: Train011 | D10: TrnLvlSmry | E10: HIGH | F10: N | G10: Y | H10: Train | J10: TRAIN_NAME | L10: Train name | M10: 181-01 | N10: Y | O10: train.train_cnst_smry.train_nm | Q10: N | R10: 1
A11: Train_Detail | B11: 10 | C11: Train051 | D11: TrnLvlSmry | E11: MEDIUM | F11: N | G11: Y | H11: Train | J11: TRAIN_TYPE_CD | L11: Train type code | M11: FRT | N11: Y | O11: atm_train.train_plan.train_type_cd atm_train.optrn.train_type_cd | Q11: Y
A12: Train_Detail | B12: 11 | C12: Train052 | D12: TrnLvlSmry | E12: MEDIUM | F12: N | G12: Y | H12: Train | J12: TRAIN_KIND_CD | L12: Train kind code | M12: PRIM | N12: Y | O12: atm_train.train_plan.train_kind_cd atm_train.optrn.train_kind_cd | Q12: Y
A13: Train_Detail | B13: 12 | C13: Train059 | D13: BMR(Qlik) | E13: MEDIUM | F13: N | G13: Y | H13: Train | J13: TYPE | L13: Train operational type | M13: OP | N13: Y | O13: train.train_cnst_smry.train_nm | Q13: Y
A14: Train_Detail | B14: 13 | C14: Train013 | D14: TrnLvlSmry | E14: HIGH | F14: Y | G14: Y | H14: Location | J14: DEPART_FSAC | K14: 1. Segment Validation: ARRIVE_FSAC <> DEPART_FSAC 2. Network Coverage: List of Unique FSAC's by Titan_Nbr&Trn_Leg_ID should cover list of FSAC's from Linked Node Table (GIS teams) sequentially" - all intermediate stations as per Linked Node Table should be covered by sequence of segments | L14: Departure FSAC code | M14: 5770 | N14: Y | O14: trkfc.trkfc_trstn.fsac_cd /eqpmv.eqpmv_rfeqp_mvmnt_event.scac_cd | Q14: N | R14: 1
A15: Train_Detail | B15: 14 | C15: Train014 | D15: TrnLvlSmry | E15: HIGH | F15: Y | G15: Y | H15: Location | J15: ARRIVE_FSAC | K15: 1. Segment Validation: ARRIVE_FSAC <> DEPART_FSAC 2. Network Coverage: List of Unique FSAC's by Titan_Nbr&Trn_Leg_ID should cover list of FSAC's from Linked Node Table (GIS teams) sequentially" - all intermediate stations as per Linked Node Table should be covered by sequence of segments | L15: Arrival FSAC code | M15: 5772 | N15: Y | O15: trkfc.trkfc_trstn.fsac_cd /eqpmv.eqpmv_rfeqp_mvmnt_event.fsac_cd | P15: SADB | Q15: N | R15: 1
A16: Train_Detail | B16: 17 | C16: Train007 | D16: TrnLvlSmry | E16: HIGH | F16: Y | G16: Y | H16: Time | J16: ARRIVE_TMS | K16: Continuity: ARRIVE_TMS > DEPART TMS by Titan&Train_Leg_ID Row 1's ARRIVE_TMS <= Row 2's DEPART_TMS sorted by Titan&Train_Leg_ID&Mark_CD&EQPMTP_NBR and order by Arrivs_TMS ASC | L16: Arrival timestamp | M16: 45870.988 | N16: Y | O16: eqpmv.eqpmv_rfeqp_mvmnt_event.report_tms | Q16: N | R16: 1
A17: Train_Detail | B17: 18 | C17: Train008 | D17: TrnLvlSmry | E17: HIGH | F17: Y | G17: Y | H17: Time | J17: DEPART_TMS | K17: Continuity: ARRIVE_TMS > DEPART TMS by Titan&Train_Leg_ID Row 1's ARRIVE_TMS <= Row 2's DEPART_TMS sorted by Titan&Train_Leg_ID&Mark_CD&EQPMTP_NBR and order by Arrivs_TMS ASC | L17: Departure timestamp | M17: 45870.901 | N17: Y | O17: eqpmv.eqpmv_rfeqp_mvmnt_event.report_tms | Q17: Y | R17: 1
A18: Train_Detail | B18: 19 | C18: Train010 | D18: TrnLvlSmry | E18: HIGH | F18: N | G18: Y | H18: Train | J18: TITAN_NBR | L18: Titan number for train | M18: 942442 | N18: Y | O18: train.train_plan_leg.mtp_titan_nbr train.optrn_leg.mtp_titan_nbr | Q18: N | R18: 1
A19: Train_Detail | B19: 20 | C19: Train021 | D19: TrnLvlSmry | E19: HIGH | F19: Y | G19: Y | H19: Miles | J19: TRAIN_MILES | K19: 1. Train Speed for segment is between 0 and 80mph (regulation) by each segment 2. if EQPMT_MILES >0, TRAIN_MILES>0 3. if GTM=0, TRAIN_MILES=0 4. TRAIN_MILES <= LIVE_LOCO_MILES (because there will be at least 1 live loco to move a train) 5. Trend analysis for DoW (Last 8 weeks vs. yesterday) and L28 vs L7 by subdivision, district, division, region, and railine to detect +/- 20% value 6. Train mile = sum of lead locomotive miles | L19: Total train miles run by a lead locomotive | M19: 7.986 | N19: Y | O19: ctnapp.ctng_line_dn.gmtry | Q19: Y | R19: 1
A20: Train_Detail | B20: 21 | C20: Train026 | D20: TrnLvlSmry | E20: HIGH | F20: Y | G20: Y | H20: Miles | J20: CONTENT_TON_MILES | K20: if Load_Empty_IND = 'Y' and EQPTMT_MILES >0, then CONTENT_TON_MILES>0 | L20: Content ton miles | M20: 16043.874 | N20: Y | O20: train.train_cnst_dtl_rail_eqpt.net_weight_tons_qty
A21: Train_Detail | B21: 22 | C21: Train081 | D21: TrnCnstDtl | E21: HIGH | F21: Y | G21: Y | H21: Equipment | J21: TARE_WEIGHT_TONS_QTY | K21: >15 tons for Rail car, >100 tons for Loco (muse min /max from history for proxy test) | L21: Tare weight in tons | M21: 66 | N21: Y | O21: train.train_cnst_dtl_rail_eqpt.tare_weight_tons_qty | Q21: N
A22: Train_Detail | B22: 23 | C22: Train088 | D22: TrnCnstDtl | E22: HIGH | F22: Y | G22: Y | H22: Equipment | J22: NET_WEIGHT_TONS_QTY | K22: If Load_Empty_IND = L and >0, Pass, False | L22: Net weight in tons | M22: 104 | N22: Y | O22: train.train_cnst_dtl_rail_eqpt.net_weight_tons_qty | Q22: N
A23: Train_Detail | B23: 25 | C23: Train025 | D23: TrnLvlSmry | E23: HIGH | F23: Y | G23: Y | H23: Weight | J23: LOCO_FULL_WEIGHT | K23: LOCO_FULL_WEIGHT/TOTAL_UNITS is between 100 and 250 tons | L23: Locomotive full weight | M23: 424 | N23: Y | O23: lcmtv.lcmtv_emis.full_weight_qty | Q23: Y
A24: Train_Detail | B24: 25 | C24: Train027 | D24: TrnLvlSmry | E24: HIGH | F24: Y | G24: Y | H24: Weight | J24: TARE_TONS | K24: 1. if asset_type = 'Locomotive", TARE_TONS = LOCO_FULL_WEIGHT 2. if asset_type = 'Railcar", TARE_TONS is between 15 and 100 tons (flatcar to heavy equipment) | L24: Total tare tons | M24: 1598.45 | N24: Y | O24: lcmtv.lcmtv_emis.full_weight_qty train.train_cnst_dtl_rail_eqpt.tare_weight_tons_qty | Q24: Y
A25: Train_Detail | B25: 26 | C25: Train015 | D25: TrnLvlSmry | E25: HIGH | F25: Y | G25: Y | H25: Time | J25: TRAIN_HRS | K25: Resonableness in speed: TRAIN_MILES / TRAIN HOURS is between 0 and 80 (mph) | L25: Train hours | M25: 2 | N25: Y | O25: ctnapp.ctng_line_dn.gmtry mvmnt_type hard coded as 'lcmtv' or 'eqpmv' train.train_cnst_dtl_rail_eqpt.lead_lcmtv_ind train.train_cnst_dtl_rail_eqpt.lcmtv_cnst_status_cd | Q25: Y | R25: 1
A26: Train_Detail | B26: 27 | C26: Train016 | D26: TrnLvlSmry | E26: HIGH | F26: Y | G26: Y | H26: Time | J26: TRAIN_MINS | K26: Resonableness in speed: TRAIN_MILES / TRAIN HOURS is between 0 and 80 (mph) | L26: Train minutes | M26: 6.02 | N26: Y | O26: Derived from ARRIVAL_TMS, DEPARTURE_TMS, TOT_MILES, TRAIN_MILES | Q26: Y | R26: 1
A27: Train_Detail | B27: 28 | C27: Train020 | D27: TrnLvlSmry | E27: HIGH | F27: Y | G27: Y | H27: Miles | J27: EQPMT_MILES | K27: if TRAIN_MILES>0, then EQPMT_MILES >0 | L27: Equipment miles | M27: 167.706 | N27: Y | O27: ctnapp.ctng_line_dn.gmtry | Q27: Y | R27: 1
A28: Train_Detail | B28: 29 | C28: Train028 | D28: TrnLvlSmry | E28: HIGH | F28: Y | G28: Y | H28: TonneMiles | J28: TARE_TON_MILES | K28: 1. TARE_TONS VALIDITY (loco between 100-250 tons, railcar between 10 and 100 tons) 2. Validation of TARE_TON_MILES (95% PROXIMITY NEEDED) (TARE_TONS X EQPMT_MILES (for Railcars)) + (TARE_TONS X LIVE_LOCO_MILES (for loco)) | L28: Tare ton miles | M28: 9379.158 | N28: Y | O28: lcmtv.lcmtv_emis.full_weight_qty train.train_cnst_dtl_rail_eqpt.tare_weight_tons_qty ctnapp.ctng_line_dn.gmtry | Q28: Y
A29: Train_Detail | B29: 30 | C29: Train029 | D29: TrnLvlSmry | E29: HIGH | F29: Y | G29: Y | H29: TonneMiles | I29: Calculated field | J29: GROSS_TON_MILES | K29: Use multiple ways to apply regression testing 1. Sum(Contents Tons + Tare Tons from railcars, live and deadhead locomotives) X Train Miles should be within 95% proximity to GROSS_TON_MILES (CONTENTS_TON_MILES + TARE_TON_MILES + DH_TARE_TON_MILES + LOCO_TARE_TON_MILES) 2. Historical consistency: check last 28 days' GTM/CONTENT_TON_MILE ratio by Suddivision vs. last 7 days (check variance over 20% (Absolute value based) 3. Historical trend: check subdivision level GTM average for the last 8 weeks' same Day of Week in comparison to yesterday's GTM excluding stat holidays (e.g. Xmas, Cinco De Mayo) 4. Train level estimates: TRAIN_NM based 5. TRAIN_MILES > 0, LIVE_LOC_MILES >0, and EQPMT_MILES >0 6. For railcar (by car by car) equipment mile should be within 95% proximity to lead locomotive miles 7. Trend analysis for DoW (Last 8 weeks vs. yesterday) and L28 vs L7 by subdivision, district, division, region, and railine to detect +/- 20% value | L29: Gross ton miles | M29: 25423.032 | N29: Y | O29: Derived from TARE_TON_MILES, DH_TARE_TON_MILES, CONTENT_TON_MILES | Q29: Y
A30: Train_Detail | B30: 31 | C30: Train023 | D30: TrnLvlSmry | E30: MEDIUM | F30: N | G30: Y | H30: TonneMiles | J30: DH_TARE_TON_MILES | L30: Deadhead tare ton miles | M30: 0 | N30: Y | O30: lcmtv.lcmtv_emis.full_weight_qty train.train_cnst_dtl_rail_eqpt.tare_weight_tons_qty ctnapp.ctng_line_dn.gmtry | Q30: Y
A31: Train_Detail | B31: 32 | C31: Train024 | D31: TrnLvlSmry | E31: HIGH | F31: Y | G31: Y | H31: TonneMiles | J31: LOCO_TARE_TON_MILES | K31: >0 | L31: Locomotive tare ton miles | M31: 3386.064 | N31: Y | O31: lcmtv.lcmtv_emis.full_weight_qty train.train_cnst_dtl_rail_eqpt.tare_weight_tons_qty ctnapp.ctng_line_dn.gmtry | Q31: Y
A32: Train_Detail | B32: 33 | C32: Train032 | D32: TrnLvlSmry | E32: HIGH | F32: Y | G32: Y | H32: Miles | J32: REV_CAR_MILES_LOADED | K32: if Load_Empty_IND = 'Y' and EQPTMT_MILES >0, then >0) Loaded railcars equipment miles (sum) | L32: Revenue car miles loaded | M32: 167.706 | N32: Y | O32: eqpmt.eqpmnt_aar_base.aar_car_cd train.train_cnst_dtl_rail_eqpt.net_weight_tons_qty ctnapp.ctng_line_dn.gmtry | Q32: Y
A33: Train_Detail | B33: 34 | C33: Train033 | D33: TrnLvlSmry | E33: HIGH | F33: Y | G33: Y | H33: Miles | J33: REV_CAR_MILES_EMPTY | K33: if Load_Empty_IND = 'N' and EQPTMT_MILES >0, then >0) non loaded railcars equipment miles (sum) | L33: Revenue car miles empty | M33: 0 | N33: Y | O33: eqpmt.eqpmnt_aar_base.aar_car_cd train.train_cnst_dtl_rail_eqpt.net_weight_tons_qty ctnapp.ctng_line_dn.gmtry | Q33: Y
A34: Train_Detail | B34: 35 | C34: Train034 | D34: TrnLvlSmry | E34: HIGH | F34: Y | G34: Y | H34: Miles | J34: LIVE_LOCO_MILES | K34: if TRAIN_MILES>0, then >0 | L34: Live locomotive miles | M34: 15.972 | N34: Y | O34: ctnapp.ctng_line_dn.gmtry dm_dim.gis_orgn_dstntn_mlg_by_stprv.miles | Q34: Y
A35: Train_Detail | B35: 36 | C35: Train035 | D35: TrnLvlSmry | E35: HIGH | F35: N | G35: Y | H35: Miles | J35: DH_LOCO_MILES | L35: Deadhead locomotive miles | M35: 0 | N35: Y | O35: ctnapp.ctng_line_dn.gmtry dm_dim.gis_orgn_dstntn_mlg_by_stprv.miles | Q35: Y | R35: ?
A36: Train_Detail | B36: 37 | C36: Train036 | D36: TrnLvlSmry | E36: HIGH | F36: Y | G36: Y | H36: Miles | J36: PASS_BUS_MILES | K36: if PASS_BUS_IND = 'Y' and EQPMT_MILES > 0, then PASS_BUS_MILES > 0 | L36: Passenger business miles | M36: 0 | N36: Y | O36: ctnapp.ctng_line_dn.gmtry dm_dim.gis_orgn_dstntn_mlg_by_stprv.miles | Q36: Y | R36: ?
A37: Train_Detail | B37: 38 | C37: Train037 | D37: TrnLvlSmry | E37: HIGH | F37: Y | G37: Y | H37: Miles | J37: WORK_CAR_MILES | K37: if WORK_CAR_IND = 'Y and EQPMT_MILES >0, then WORK_CAR_MILES >0 | L37: Work car miles | M37: 0 | N37: Y | O37: eqpmt.eqpmnt_aar_base.aar_car_cd ctnapp.ctng_line_dn.gmtry trkfc.trkfcg_sbdvsn.sbdvsn_id trkfc.trkfcg_fxpla_track_lctn_dn.rfrnc_low_miles_qty dm_dim.gis_orgn_dstntn_mlg_by_stprv.miles dm_dim.dim_subdvsn_zone.high_track_mile dm_dim.dim_subdvsn_zone.low_track_mile | Q37: Y
A38: Train_Detail | B38: 39 | C38: Train038 | D38: TrnLvlSmry | E38: LOW | F38: N | G38: X | H38: Miles | J38: CABOOSE_MILES | L38: Caboose miles | M38: 0 | N38: Y | O38: eqpmt.eqpmnt_aar_base.aar_car_cd ctnapp.ctng_line_dn.gmtry dm_dim.gis_orgn_dstntn_mlg_by_stprv.miles | Q38: Y
A39: Train_Detail | B39: 40 | C39: Train039 | D39: TrnLvlSmry | E39: HIGH | F39: Y | G39: Y | H39: Miles | J39: LIVE_LOCO_HP_MILES | K39: if TRAIN_MILES>0, LIVE_LOCO_HP_MILES >0 | L39: Live locomotive horsepower miles | M39: 69478.2 | N39: Y | O39: lcmtv.lcmtv_emis.hrspwr_qty ctnapp.ctng_line_dn.gmtry dm_dim.gis_orgn_dstntn_mlg_by_stprv.miles | Q39: Y
A40: Train_Detail | B40: 41 | C40: Train040 | D40: TrnLvlSmry | E40: MEDIUM | F40: N | G40: Y | H40: Miles | J40: DH_LOCO_HP_MILES | L40: Deadhead locomotive horsepower miles | M40: 0 | N40: Y | O40: lcmtv.lcmtv_emis.hrspwr_qty ctnapp.ctng_line_dn.gmtry dm_dim.gis_orgn_dstntn_mlg_by_stprv.miles | Q40: Y
...

Sheet NETWORK_COVERAGE
B1: PoC - Network Coverage
B3: Sub | C3: STATION | D3: SEGMENT | E3: DIRECTION | F3: FSAC | G3: MILES | H3: ELAPSED_HRS | I3: Time_Audit | J3: SPEED | K3: Speed Audit (0 - 80mph) | L3: AWS | M3: AWS Audit | N3: SADB & AZURE | O3: SADB Audit | P3: UNIONED NETWORK | Q3: Network Audit
B4: CASCADE | C4: VANCOUVER | E4: E | F4: 9700 | L4: X | M4: Fail | N4: Y | O4: Pass | P4: Y | Q4: Pass
B5: CASCADE | C5: DUNLEVY | D5: =C4&"-"&C5 -> VANCOUVER-DUNLEVY | E5: E | F5: 9768 | G5: 0.4 | H5: -0.02 | I5: Fail | J5: =G5/H5 -> -20 | K5: Fail | L5: Y | M5: Pass | N5: X | O5: Fail | P5: Y | Q5: Pass
B6: CASCADE | C6: HEATLEY | D6: =C5&"-"&C6 -> DUNLEVY-HEATLEY | E6: E | F6: 9769 | G6: 0.5 | H6: 0.04 | I6: Pass | J6: =G6/H6 -> 12.5 | K6: Pass | L6: Y | M6: Pass | N6: X | O6: Fail | P6: Y | Q6: Pass
B7: CASCADE | C7: WILLISTON | D7: =C6&"-"&C7 -> HEATLEY-WILLISTON | E7: E | F7: 9774 | G7: 0.9 | H7: 0.05 | I7: Pass | J7: =G7/H7 -> 18 | K7: Pass | L7: Y | M7: Pass | N7: X | O7: Fail | P7: Y | Q7: Pass
B8: CASCADE | C8: RENFREW | D8: =C7&"-"&C8 -> WILLISTON-RENFREW | E8: E | F8: 9781 | G8: 1 | H8: 0.02 | I8: Pass | J8: =G8/H8 -> 50 | K8: Pass | L8: Y | M8: Pass | N8: X | O8: Fail | P8: Y | Q8: Pass
B9: CASCADE | C9: SECOND NARROWS | D9: =C8&"-"&C9 -> RENFREW-SECOND NARROWS | E9: E | F9: 9705 | G9: 0.7 | H9: 0.02 | I9: Pass | J9: =G9/H9 -> 35 | K9: Pass | L9: Y | M9: Pass | N9: X | O9: Fail | P9: Y | Q9: Pass
B10: CASCADE | C10: BARNET | D10: =C9&"-"&C10 -> SECOND NARROWS-BARNET | E10: E | F10: 9695 | G10: 0.4 | H10: 0.02 | I10: Pass | J10: =G10/H10 -> 20 | K10: Pass | L10: Y | M10: Pass | N10: X | O10: Fail | P10: Y | Q10: Pass
B11: CASCADE | C11: CASSIN | D11: =C10&"-"&C11 -> BARNET-CASSIN | E11: E | F11: 9657 | G11: 0.9 | H11: 0.01 | I11: Pass | J11: =G11/H11 -> 90 | K11: Fail | L11: Y | M11: Pass | N11: X | O11: Fail | P11: Y | Q11: Pass
B12: CASCADE | C12: PORT MOODY | D12: =C11&"-"&C12 -> CASSIN-PORT MOODY | E12: E | F12: 9693 | G12: 0.1 | H12: 0.02 | I12: Pass | J12: =G12/H12 -> 5 | K12: Pass | L12: X | M12: Fail | N12: X | O12: Fail | P12: X | Q12: Fail
B13: CASCADE | C13: SETO | D13: =C12&"-"&C13 -> PORT MOODY-SETO | E13: E | F13: 9687 | G13: 0.2 | H13: 0.02 | I13: Pass | J13: =G13/H13 -> 10 | K13: Pass | L13: Y | M13: Pass | N13: X | O13: Fail | P13: Y | Q13: Pass
B14: CASCADE | C14: WESTWOOD | D14: =C13&"-"&C14 -> SETO-WESTWOOD | E14: E | F14: 9766 | G14: 0.9 | H14: 0.02 | I14: Pass | J14: =G14/H14 -> 45 | K14: Pass | L14: Y | M14: Pass | N14: X | O14: Fail | P14: Y | Q14: Pass
B15: CASCADE | C15: MACAULAY | D15: =C14&"-"&C15 -> WESTWOOD-MACAULAY | E15: E | F15: 9688 | G15: 0.2 | H15: 0.02 | I15: Pass | J15: =G15/H15 -> 10 | K15: Pass | L15: Y | M15: Pass | N15: X | O15: Fail | P15: Y | Q15: Pass
B16: CASCADE | C16: COQUITLAM | D16: =C15&"-"&C16 -> MACAULAY-COQUITLAM | E16: E | F16: 9684 | G16: 0.7 | H16: 0.02 | I16: Pass | J16: =G16/H16 -> 35 | K16: Pass | L16: X | M16: Fail | N16: Y | O16: Pass | P16: Y | Q16: Pass
C18: FOUND ONLY IN SADB
C19: FOUND ONLY IN AWS

Sheet Jira
A1: Team | B1: Assignee | C1: Issue-key | D1: Status | E1: ETA | F1: Summary | G1: Description | W1: Summary | X1: Issue key | Y1: Issue id | Z1: Parent id | AA1: Issue Type | AB1: Status | AC1: Project key | AD1: Project name | AE1: Project type | AF1: Project lead | AG1: Project description | AH1: Project url | AI1: Priority | AJ1: Resolution | AK1: Assignee | AL1: Reporter | AM1: Creator | AN1: Created | AO1: Updated | AP1: Last Viewed | AQ1: Resolved | AR1: Affects Version/s | AS1: Fix Version/s | AT1: Component/s | AU1: Due Date | AV1: Votes | AW1: Labels | AX1: Description | AY1: Watchers | AZ1: Watchers | BA1: Watchers | BB1: Watchers | BC1: Watchers | BD1: Log Work | BE1: Original Estimate | BF1: Remaining Estimate | BG1: Time Spent | BH1: Work Ratio | BI1: Σ Original Estimate | BJ1: Σ Remaining Estimate | BK1: Σ Time Spent | BL1: Inward issue link (Blocks) | BM1: Outward issue link (Relates) | BN1: Attachment | BO1: Attachment | BP1: Custom field (Acceptance Criteria) | BQ1: Custom field (Build Number) | BR1: Custom field (Business Value) | BS1: Custom field (Defect Type) | BT1: Custom field (DeployToTest) | BU1: Custom field (Epic Link) | BV1: Custom field (Epic/Theme) | BW1: Custom field (External Story Number) | BX1: Custom field (External issue ID) | BY1: Custom field (Flagged) | BZ1: Custom field (Original story points) | CA1: Custom field (Parent Link) | CB1: Custom field (Rank) | CC1: Custom field (Requested by) | CD1: Sprint | CE1: Custom field (Story Points) | CF1: Custom field (Target end) | CG1: Custom field (Target start) | CH1: Custom field (Team) | CI1: Custom field (qTest Defect Code) | CJ1: Comment | CK1: Comment | CL1: Comment | CM1: Comment | CN1: Comment | CO1: Comment | CP1: Comment | CQ1: Comment | CR1: Comment | CS1: Comment | CT1: Comment
A2: =VLOOKUP(AK2,members!$A:$C,3,FALSE) -> MDM | B2: =VLOOKUP(AK2,members!$A:$C,2,FALSE) -> Nikhil | C2: =X2 -> RPD-82 | D2: =AB2 -> To Do | E2: =AU2 -> 46002 | F2: =W2 -> DIM equipment mapping document provision to QE team (VishnuB) | G2: =AX2 -> [~seh0018] to provide mapping documents to [~bor0475] [~sid0070] and [~sel0052] | W2: DIM equipment mapping document provision to QE team (VishnuB) | X2: RPD-82 | Y2: 190493 | Z2: 186078 | AA2: Sub-task | AB2: To Do | AC2: RPD | AD2: Rail360 Product Development | AE2: software | AF2: las0044 | AI2: 3-High | AK2: seh0018 | AL2: woo0234 | AM2: woo0234 | AN2: 46001.48 | AO2: 46001.48 | AP2: 46002.459 | AU2: 46002 | AV2: 0 | AW2: Rail360 | AX2: [~seh0018] to provide mapping documents to [~bor0475] [~sid0070] and [~sel0052] | AY2: woo0234 | CB2: 1|i0i838:
A3: =VLOOKUP(AK3,members!$A:$C,3,FALSE) -> ETL | B3: =VLOOKUP(AK3,members!$A:$C,2,FALSE) -> Naveen | C3: =X3 -> RPD-79 | D3: =AB3 -> In Progress | E3: =AU3 -> 46000 | F3: =W3 -> Data Ingestion based on Squadron's analysis | G3: =AX3 -> [~knxn12] to complete by working with Squadron for data ingestion. | W3: Data Ingestion based on Squadron's analysis | X3: RPD-79 | Y3: 190165 | AA3: Task | AB3: In Progress | AC3: RPD | AD3: Rail360 Product Development | AE3: software | AF3: las0044 | AI3: 3-High | AK3: knxn12 | AL3: woo0234 | AM3: woo0234 | AN3: 45999.478 | AO3: 46001.476 | AP3: 46001.475 | AU3: 46000 | AV3: 0 | AW3: Rail360 | AX3: [~knxn12] to complete by working with Squadron for data ingestion. | AY3: woo0234 | CB3: 1|i0i63g: | CJ3: 10/Dec/25 11:24 AM;woo0234;[~knxn12] to discuss with [~ngu0018] for injection options regarding historical data refreshing strategies. regarding Oracle/ IICS / CDC;;; | CK3: 10/Dec/25 11:25 AM;woo0234;[~mor0460] supports work sametime for tables that has less sensitivity [~tha0073] [~pat0606] to work together.;;;
A4: =VLOOKUP(AK4,members!$A:$C,3,FALSE) -> BDA | B4: =VLOOKUP(AK4,members!$A:$C,2,FALSE) -> VPS | C4: =X4 -> RPD-69 | D4: =AB4 -> In Progress | E4: =AU4 -> 45996 | F4: =W4 -> ER Diagram for Gold Layer fields | G4: =AX4 -> Data model needed | W4: ER Diagram for Gold Layer fields | X4: RPD-69 | Y4: 189315 | AA4: Task | AB4: In Progress | AC4: RPD | AD4: Rail360 Product Development | AE4: software | AF4: las0044 | AI4: 3-High | AK4: cvps10 | AL4: cvps10 | AM4: cvps10 | AN4: 45993.477 | AO4: 46002.438 | AP4: 46001.469 | AU4: 45996 | AV4: 0 | AX4: Data model needed | AY4: cvps10 | AZ4: woo0234 | CB4: 1|i0i1z8: | CJ4: 09/Dec/25 11:10 AM;woo0234;[~cvps10] provided ER diagram to [~pat0606] on 12/8 for review_x000D_ _x000D_ ;;; | CK4: 11/Dec/25 10:31 AM;cvps10;Will create data model for the entire gold layer fields. That's why putting it in progress. Awaiting access to Erwin;;;
A5: =VLOOKUP(AK5,members!$A:$C,3,FALSE) -> ETL | B5: =VLOOKUP(AK5,members!$A:$C,2,FALSE) -> Naveen | C5: =X5 -> RPD-73 | D5: =AB5 -> In Progress | E5: =AU5 -> 46003 | F5: =W5 -> MDM set up - Snowflake account and its representative needed | G5: =AX5 -> [~seh0018] requires an answer from Squadron to identify whom in Squadron covered / worked out to set up connection (this is about dimension table such as dim equipment, dim location, dim commodity, and dim customers)_x000D_ _x000D_ _x000D_ _x000D_ [~knxn12] / [~seh0018] / [~tha0073] / [~dan0243] to discuss 12/5 | W5: MDM set up - Snowflake account and its representative needed | X5: RPD-73 | Y5: 190021 | Z5: 186070 | AA5: Sub-task | AB5: In Progress | AC5: RPD | AD5: Rail360 Product Development | AE5: software | AF5: las0044 | AI5: 3-High | AK5: knxn12 | AL5: woo0234 | AM5: woo0234 | AN5: 45996.463 | AO5: 46001.467 | AP5: 46001.467 | AU5: 46003 | AV5: 0 | AW5: Rail360 | AX5: [~seh0018] requires an answer from Squadron to identify whom in Squadron covered / worked out to set up connection (this is about dimension table such as dim equipment, dim location, dim commodity, and dim customers)_x000D_ _x000D_ _x000D_ _x000D_ [~knxn12] / [~seh0018] / [~tha0073] / [~dan0243] to discuss 12/5 | AY5: dan0243 | AZ5: woo0234 | CB5: 1|i0i57w: | CJ5: 10/Dec/25 10:32 AM;dan0243;[~knxn12] - Can you please help here to create a service account and provide the details to Nikhil. Kindly let us know in case you need any help in creation of SA.;;; | CK5: 10/Dec/25 11:13 AM;woo0234;Naveen to own provision of account to MDM team for both public and private keys for Squadron members.;;;
A6: =VLOOKUP(AK6,members!$A:$C,3,FALSE) -> Squadron | B6: =VLOOKUP(AK6,members!$A:$C,2,FALSE) -> Harshil Patel | C6: =X6 -> RPD-65 | D6: =AB6 -> In Progress | E6: =AU6 -> 46002 | F6: =W6 -> SnowFlake ETL Plan - Bronze to Silver solution to provide - document / email needed | G6: =AX6 -> Document that_x000D_ _x000D_ includes methodologies out of below example options._x000D_ _x000D_ include data models for Silver Layers_x000D_ _x000D_ _x000D_ _x000D_ 1) DBT_x000D_ _x000D_ 2) Store Procedures_x000D_ _x000D_ 3) Snow Park | W6: SnowFlake ETL Plan - Bronze to Silver solution to provide - document / email needed | X6: RPD-65 | Y6: 189013 | AA6: Task | AB6: In Progress | AC6: RPD | AD6: Rail360 Product Development | AE6: software | AF6: las0044 | AI6: 3-High | AK6: pat0606 | AL6: woo0234 | AM6: woo0234 | AN6: 45988.469 | AO6: 46001.465 | AP6: 46001.465 | AU6: 46002 | AV6: 0 | AW6: Rail360 | AX6: Document that_x000D_ _x000D_ includes methodologies out of below example options._x000D_ _x000D_ include data models for Silver Layers_x000D_ _x000D_ _x000D_ _x000D_ 1) DBT_x000D_ _x000D_ 2) Store Procedures_x000D_ _x000D_ 3) Snow Park | AY6: cvps10 | AZ6: dan0243 | BA6: woo0234 | BN6: 10/Dec/25 10:11 AM;dan0243;Snowflake Native Capabilities_v2.docx;https://jira.cpr.ca/secure/attachment/166180/Snowflake+Native+Capabilities_v2.docx | CB6: 1|i0i064: | CJ6: 03/Dec/25 11:07 AM;cvps10;Awaiting transformation plan and ETL tool;;; | CK6: 09/Dec/25 10:09 AM;dan0243;9/12 - This is dependent on the data modeling documents which we are closing working on.;;; | CL6: 09/Dec/25 11:23 AM;woo0234;[~pat0606] will share document today 12/9;;; | CM6: 10/Dec/25 10:09 AM;dan0243;10/12 - The detailed documents on the transformation part have been sent across once we finalized the approach based on data model readiness._x000D_ _x000D_ _x000D_ _x000D_ I am attaching the sheet here as well for reference.[^Snowflake Native Capabilities_v2.docx];;; | CN6: 10/Dec/25 11:09 AM;woo0234;follow up a call 12/11 among [~ngu0018] [~moh0106] including both architect and Squadron/Celebal members;;;
A7: =VLOOKUP(AK7,members!$A:$C,3,FALSE) -> ETL | B7: =VLOOKUP(AK7,members!$A:$C,2,FALSE) -> Naveen | C7: =X7 -> RPD-81 | D7: =AB7 -> To Do | E7: =AU7 -> 46001 | F7: =W7 -> Data injection job to start from source to bronze | G7: =AX7 -> 0 | W7: Data injection job to start from source to bronze | X7: RPD-81 | Y7: 190352 | AA7: Task | AB7: To Do | AC7: RPD | AD7: Rail360 Product Development | AE7: software | AF7: las0044 | AI7: 3-High | AK7: knxn12 | AL7: woo0234 | AM7: woo0234 | AN7: 46000.477 | AO7: 46000.477 | AP7: 46001.459 | AU7: 46001 | AV7: 0 | AW7: Rail360 | AY7: woo0234 | CB7: 1|i0i78c:
A8: =VLOOKUP(AK8,members!$A:$C,3,FALSE) -> ETL | B8: =VLOOKUP(AK8,members!$A:$C,2,FALSE) -> Jatinder | C8: =X8 -> RPD-29 | D8: =AB8 -> In Progress | E8: =AU8 -> 46052 | F8: =W8 -> Identifying solutions to bring track/mileage info for Regulatory Tonnage Proj. | G8: =AX8 -> in the past, during the development of reg tonnage with FTI, csv file was created in order to provide detailed mapping of mileages and types of track information in CPKC network._x000D_ _x000D_ [~sin0404] to interview key stakeholders (Karthik / Jincy) to obtain source file._x000D_ _x000D_ _x000D_ _x000D_ Track level reporting is mainly sourcing legacy BMR data as per [~sau0093] so track information from business team are not fully incorporated in CPKC's data set. | W8: Identifying solutions to bring track/mileage info for Regulatory Tonnage Proj. | X8: RPD-29 | Y8: 186287 | AA8: Task | AB8: In Progress | AC8: RPD | AD8: Rail360 Product Development | AE8: software | AF8: las0044 | AI8: 3-High | AK8: sin0404 | AL8: woo0234 | AM8: woo0234 | AN8: 45954.482 | AO8: 46001.042 | AP8: 46001.458 | AU8: 46052 | AV8: 0 | AW8: Rail360 | AX8: in the past, during the development of reg tonnage with FTI, csv file was created in order to provide detailed mapping of mileages and types of track information in CPKC network._x000D_ _x000D_ [~sin0404] to interview key stakeholders (Karthik / Jincy) to obtain source file._x000D_ _x000D_ _x000D_ _x000D_ Track level reporting is mainly sourcing legacy BMR data as per [~sau0093] so track information from business team are not fully incorporated in CPKC's data set. | AY8: cvps10 | AZ8: woo0234 | CB8: 1|i0hkbg: | CJ8: 03/Dec/25 11:24 AM;cvps10;Phase 1 only 2 canadian subs, so difficult to test proximity with regulatory tonnage. Will look at it after first draft of tonnage is ready. We can compare two canadian subdivision data mid Jan (after Rail360 is ready for UAT);;;
A9: =VLOOKUP(AK9,members!$A:$C,3,FALSE) -> BDA | B9: =VLOOKUP(AK9,members!$A:$C,2,FALSE) -> Sangtae | C9: =X9 -> RPD-50 | D9: =AB9 -> In Progress | E9: =AU9 -> 46010 | F9: =W9 -> Product Design review from Squadron | G9: =AX9 -> 0 | W9: Product Design review from Squadron | X9: RPD-50 | Y9: 188011 | AA9: Task | AB9: In Progress | AC9: RPD | AD9: Rail360 Product Development | AE9: software | AF9: las0044 | AI9: 3-High | AK9: woo0234 | AL9: ana0017 | AM9: ana0017 | AN9: 45974.465 | AO9: 46001.041 | AP9: 46001.041 | AU9: 46010 | AV9: 0 | AY9: ana0017 | AZ9: cvps10 | CB9: 1|i0hub8: | CJ9: 02/Dec/25 11:34 AM;cvps10;In progress - regulatory reporting info to be fulfilled;;;
A10: =VLOOKUP(AK10,members!$A:$C,3,FALSE) -> Architect | B10: =VLOOKUP(AK10,members!$A:$C,2,FALSE) -> Karthik | C10: =X10 -> RPD-67 | D10: =AB10 -> To Do | E10: =AU10 -> 45992 | F10: =W10 -> CSN review for direction (regarding issues) | G10: =AX10 -> plan to navigate our options regarding_x000D_ _x000D_ duplicates_x000D_ _x000D_ changes in CSN during single trip | W10: CSN review for direction (regarding issues) | X10: RPD-67 | Y10: 189059 | AA10: Task | AB10: To Do | AC10: RPD | AD10: Rail360 Product Development | AE10: software | AF10: las0044 | AI10: 3-High | AK10: rav0018 | AL10: woo0234 | AM10: woo0234 | AN10: 45989.473 | AO10: 45989.473 | AP10: 46001.022 | AU10: 45992 | AV10: 0 | AW10: Rail360 | AX10: plan to navigate our options regarding_x000D_ _x000D_ duplicates_x000D_ _x000D_ changes in CSN during single trip | AY10: woo0234 | CB10: 1|i0i0fo:
A11: =VLOOKUP(AK11,members!$A:$C,3,FALSE) -> QE | B11: =VLOOKUP(AK11,members!$A:$C,2,FALSE) -> Manooj | C11: =X11 -> RPD-42 | D11: =AB11 -> In Progress | E11: =AU11 -> 45971 | F11: =W11 -> UAT related ideas gathering / high level scenarios | G11: =AX11 -> [~sel0052] [~sid0070] will contact/introduce QA team to start getting involved. (test strategy sharing may be starting point)_x000D_ _x000D_ [~woo0234] will set up 40-45 mins call with [~ste0370] 's team and QA team by 2nd week of November. | W11: UAT related ideas gathering / high level scenarios | X11: RPD-42 | Y11: 187294 | Z11: 186087 | AA11: Sub-task | AB11: In Progress | AC11: RPD | AD11: Rail360 Product Development | AE11: software | AF11: las0044 | AI11: 3-High | AK11: sel0052 | AL11: woo0234 | AM11: woo0234 | AN11: 45966.485 | AO11: 45993.481 | AP11: 46001.022 | AU11: 45971 | AV11: 0 | AW11: Rail360 | AX11: [~sel0052] [~sid0070] will contact/introduce QA team to start getting involved. (test strategy sharing may be starting point)_x000D_ _x000D_ [~woo0234] will set up 40-45 mins call with [~ste0370] 's team and QA team by 2nd week of November. | AY11: ana0017 | AZ11: cvps10 | BA11: woo0234 | CB11: 1|i0hpxw: | CJ11: 13/Nov/25 11:06 AM;ana0017;Team is Meeting with Business at 1030 MST 13/11 to discuss._x000D_ _x000D_ ;;; | CK11: 19/Nov/25 11:22 AM;cvps10;Awaiting feedback on data quality from Paul's team_x000D_ And UAT discussion yet to be done;;; | CL11: 02/Dec/25 11:32 AM;cvps10;Metrics threshold discussion with Paul and team - Sangtae;;;
A12: =VLOOKUP(AK12,members!$A:$C,3,FALSE) -> ETL | B12: =VLOOKUP(AK12,members!$A:$C,2,FALSE) -> Naveen | C12: =X12 -> RPD-55 | D12: =AB12 -> In Progress | E12: =AU12 -> 45981 | F12: =W12 -> Service Account SET UP request | G12: =AX12 -> ACC/DEV/PROD_x000D_ * MDW ( A8087)_x000D_ * EDW (ORAA414)_x000D_ * SADB (ORAA430)_x000D_ * Snowflake_x000D_ * Azure_x000D_ * AWS_x000D_ _x000D_ | W12: Service Account SET UP request | X12: RPD-55 | Y12: 188639 | Z12: 188628 | AA12: Sub-task | AB12: In Progress | AC12: RPD | AD12: Rail360 Product Development | AE12: software | AF12: las0044 | AI12: 3-High | AK12: knxn12 | AL12: woo0234 | AM12: woo0234 | AN12: 45981.482 | AO12: 45986.471 | AP12: 46001.022 | AU12: 45981 | AV12: 0 | AW12: Rail360 | AX12: ACC/DEV/PROD_x000D_ * MDW ( A8087)_x000D_ * EDW (ORAA414)_x000D_ * SADB (ORAA430)_x000D_ * Snowflake_x000D_ * Azure_x000D_ * AWS_x000D_ _x000D_ | AY12: woo0234 | CB12: 1|i0hy1g: | CJ12: 20/Nov/25 1:29 PM;woo0234;requested as RAILSDC name to be approved by [~gho0014] / followed by [~las0044] ;;; | CK12: 21/Nov/25 11:11 AM;woo0234;[~knxn12] to re-create request based on service team's format.;;; | CL12: 24/Nov/25 11:23 AM;woo0234;SADB/EDW DEV created_x000D_ _x000D_ MDW to be created;;; | CM12: 25/Nov/25 11:18 AM;woo0234;Oracle: use same account_x000D_ _x000D_ In discussion with Service Fulfillment Team.;;;
A13: =VLOOKUP(AK13,members!$A:$C,3,FALSE) -> Cloud | B13: =VLOOKUP(AK13,members!$A:$C,2,FALSE) -> Ruben | C13: =X13 -> RPD-8 | D13: =AB13 -> Done | E13: =AU13 -> 45954 | F13: =W13 -> AWS access grant for Rail 360 | G13: =AX13 -> Obtain Access to AWS for 3 core data sources, Wi-Tronics, Sentinel, and Geo-fence for all participants (need an access to table) | W13: AWS access grant for Rail 360 | X13: RPD-8 | Y13: 186081 | AA13: Task | AB13: Done | AC13: RPD | AD13: Rail360 Product Development | AE13: software | AF13: las0044 | AI13: 3-High | AJ13: Done | AK13: gue0154 | AL13: woo0234 | AM13: woo0234 | AN13: 45951.583 | AO13: 45982.474 | AP13: 46001.02 | AQ13: 45982.474 | AU13: 45954 | AV13: 0 | AW13: Rail360 | AX13: Obtain Access to AWS for 3 core data sources, Wi-Tronics, Sentinel, and Geo-fence for all participants (need an access to table) | AY13: cvps10 | AZ13: woo0234 | CB13: 1|i0hj38: | CJ13: 28/Oct/25 11:40 AM;woo0234;[~gue0154] and [~bry0059] will provide 2 table access that includes train and locomotive information. ;;; | CK13: 19/Nov/25 11:11 AM;cvps10;AWS access to be granted to Squadron folks.;;;
A14: =VLOOKUP(AK14,members!$A:$C,3,FALSE) -> QE | B14: =VLOOKUP(AK14,members!$A:$C,2,FALSE) -> Raheel | C14: =X14 -> RPD-68 | D14: =AB14 -> Done | E14: 46051 | F14: =W14 -> Raheel to discuss with Jatinder/Naveen for Source to Bronze pipeline builiding | G14: =AX14 -> there should be threshold and monitoring of performance related to data transfer from sources to bronze layer monitored/governed by CPKC's system/employees._x000D_ _x000D_ need input / plan and employees in charge prior to developing. | W14: Raheel to discuss with Jatinder/Naveen for Source to Bronze pipeline builiding | X14: RPD-68 | Y14: 189060 | AA14: Task | AB14: Done | AC14: RPD | AD14: Rail360 Product Development | AE14: software | AF14: las0044 | AI14: 3-High | AJ14: Done | AK14: sid0070 | AL14: woo0234 | AM14: woo0234 | AN14: 45989.479 | AO14: 45993.486 | AP14: 46001.019 | AQ14: 45993.486 | AU14: 45992 | AV14: 0 | AW14: Rail360 | AX14: there should be threshold and monitoring of performance related to data transfer from sources to bronze layer monitored/governed by CPKC's system/employees._x000D_ _x000D_ need input / plan and employees in charge prior to developing. | AY14: woo0234 | CB14: 1|i0i0fw: | CJ14: 01/Dec/25 11:06 AM;woo0234;meeting to be held for available testing options prior to all data pipeline is built mainly bronze side data but not limited to led by [~sid0070] with [~knxn12] ;;;
A15: =VLOOKUP(AK15,members!$A:$C,3,FALSE) -> Architect | B15: =VLOOKUP(AK15,members!$A:$C,2,FALSE) -> David | C15: =X15 -> RPD-76 | D15: =AB15 -> In Progress | E15: =AU15 -> 46007 | F15: =W15 -> Data Modeling Session among Architect, Celebal, and Squadron | G15: =AX15 -> [~ngu0018] to work with celebal and squadron to understand their approaches regarding transition from bronze to gold.... | W15: Data Modeling Session among Architect, Celebal, and Squadron | X15: RPD-76 | Y15: 190158 | AA15: Task | AB15: In Progress | AC15: RPD | AD15: Rail360 Product Development | AE15: software | AF15: las0044 | AI15: 3-High | AK15: ngu0018 | AL15: woo0234 | AM15: woo0234 | AN15: 45999.461 | AO15: 46001.434 | AP15: 46001.018 | AU15: 46007 | AV15: 0 | AW15: Rail360 | AX15: [~ngu0018] to work with celebal and squadron to understand their approaches regarding transition from bronze to gold.... | AY15: ngu0018 | AZ15: woo0234 | CB15: 1|i0i62c: | CJ15: 10/Dec/25 10:18 AM;ngu0018;Had to reschedule meeting to Dec 16th due to conflicts on the original schedule on Dec 6th. Reason to push all the way to next week is Karthik is on AV from Dec 10 -12 and we need his participation and input. ;;;
A16: =VLOOKUP(AK16,members!$A:$C,3,FALSE) -> BDA | B16: =VLOOKUP(AK16,members!$A:$C,2,FALSE) -> VPS | C16: =X16 -> RPD-62 | D16: =AB16 -> Done | E16: =AU16 -> 45985 | F16: =W16 -> Logic review with Manzoor | G16: =AX16 -> [~sau0093] and [~cvps10] to reach out to [~bab0040] to review set/lift logic_x000D_ _x000D_ Use workorder information_x000D_ _x000D_ consider using OPTRN TABLE and TRAIN.TRAIN_ACTUAL_WORK_x000D_ _x000D_ YARD_RPRTNG_IND = 'Y' for b-flag station in TRAIN_PLAN_EVENT table | W16: Logic review with Manzoor | X16: RPD-62 | Y16: 188704 | Z16: 188014 | AA16: Sub-task | AB16: Done | AC16: RPD | AD16: Rail360 Product Development | AE16: software | AF16: las0044 | AI16: 3-High | AJ16: Done | AK16: cvps10 | AL16: woo0234 | AM16: woo0234 | AN16: 45982.472 | AO16: 45992.471 | AP16: 46001.018 | AQ16: 45992.471 | AU16: 45985 | AV16: 0 | AX16: [~sau0093] and [~cvps10] to reach out to [~bab0040] to review set/lift logic_x000D_ _x000D_ Use workorder information_x000D_ _x000D_ consider using OPTRN TABLE and TRAIN.TRAIN_ACTUAL_WORK_x000D_ _x000D_ YARD_RPRTNG_IND = 'Y' for b-flag station in TRAIN_PLAN_EVENT table | AY16: bab0040 | AZ16: woo0234 | CB16: 1|i0hyf8: | CJ16: 21/Nov/25 3:59 PM;bab0040;this is the query used in train semantic for lift setoff in p8087:_x000D_ _x000D_ _x000D_ _x000D_ select LIFT_SET_IND,taw.TYES_TRAIN_ID, tll.TRAIN_CNST_ID, FSAC_CD, SCAC_CD, ROUTE_POINT_SQNC_NBR, _x000D_ coalesce(INTRMD_ROUTE_POINT_SQNC_NBR,0) as INTRMD_ROUTE_POINT_SQNC_NBR , count(*) as CNT_x000D_ from atm_train.TRAIN_ACTUAL_WORK taw with (nolock) --P89_x000D_ join (select * from DM_TRAIN.TRAIN_LAST_LCTN with (nolock) where EDW_UPDATE_TMS>= getdate()-1_x000D_ ) tll _x000D_ on taw.TYES_TRAIN_ID=tll.TYES_TRAIN_ID_x000D_ where taw.cnvyng_mark_cd is null_x000D_ group by LIFT_SET_IND, taw.TYES_TRAIN_ID, FSAC_CD,SCAC_CD, tll.TRAIN_CNST_ID,INTRMD_ROUTE_POINT_SQNC_NBR, ROUTE_POINT_SQNC_NBR;;;
A17: =VLOOKUP(AK17,members!$A:$C,3,FALSE) -> Squadron | B17: =VLOOKUP(AK17,members!$A:$C,2,FALSE) -> Hisham | C17: =X17 -> RPD-70 | D17: =AB17 -> Backlog | E17: =AU17 -> 46001 | F17: =W17 -> Identifying SAP tables for Rail360 | G17: =AX17 -> [~dan0243] to check with [~che0157] | W17: Identifying SAP tables for Rail360 | X17: RPD-70 | Y17: 189941 | AA17: Story | AB17: Backlog | AC17: RPD | AD17: Rail360 Product Development | AE17: software | AF17: las0044 | AI17: 3-High | AK17: dan0243 | AL17: dan0243 | AM17: dan0243 | AN17: 45994.62 | AO17: 45999.463 | AP17: 46001.016 | AU17: 46001 | AV17: 0 | AX17: [~dan0243] to check with [~che0157] | AY17: dan0243 | AZ17: woo0234 | CB17: 1|i0i4qs: | CJ17: 08/Dec/25 11:07 AM;woo0234;SAP BW is part of it;;;
A18: =VLOOKUP(AK18,members!$A:$C,3,FALSE) -> Squadron | B18: =VLOOKUP(AK18,members!$A:$C,2,FALSE) -> Babu | C18: =X18 -> RPD-78 | D18: =AB18 -> To Do | E18: =AU18 -> 46007 | F18: =W18 -> Snowflake Data Model Creation - Bronze to Silver | G18: =AX18 -> [~tha0073] to update data model within snowflake_x000D_ _x000D_ | W18: Snowflake Data Model Creation - Bronze to Silver | X18: RPD-78 | Y18: 190161 | Z18: 189315 | AA18: Sub-task | AB18: To Do | AC18: RPD | AD18: Rail360 Product Development | AE18: software | AF18: las0044 | AI18: 3-High | AK18: tha0073 | AL18: woo0234 | AM18: woo0234 | AN18: 45999.472 | AO18: 45999.473 | AP18: 46001.015 | AU18: 46007 | AV18: 0 | AW18: Rail360 | AX18: [~tha0073] to update data model within snowflake_x000D_ _x000D_ | AY18: woo0234 | CB18: 1|i0i630:
A19: =VLOOKUP(AK19,members!$A:$C,3,FALSE) -> Celebal | B19: =VLOOKUP(AK19,members!$A:$C,2,FALSE) -> Jatin | C19: =X19 -> RPD-75 | D19: =AB19 -> Done | E19: =AU19 -> 45996 | F19: =W19 -> AI - Foundation building check list to be completed | G19: =AX19 -> [~aro0027] to complete AI foundation checklist for Rail 360's (all layers) | W19: AI - Foundation building check list to be completed | X19: RPD-75 | Y19: 190030 | Z19: 190029 | AA19: Sub-task | AB19: Done | AC19: RPD | AD19: Rail360 Product Development | AE19: software | AF19: las0044 | AI19: 3-High | AJ19: Done | AK19: aro0027 | AL19: woo0234 | AM19: woo0234 | AN19: 45996.493 | AO19: 46001.226 | AP19: 46001.015 | AQ19: 46001.226 | AU19: 45996 | AV19: 0 | AW19: Rail360 | AX19: [~aro0027] to complete AI foundation checklist for Rail 360's (all layers) | AY19: aro0027 | AZ19: woo0234 | CB19: 1|i0i59w: | CJ19: 08/Dec/25 8:22 AM;aro0027;I have created the AI Foundation Checklist for Rail 360's_x000D_ _x000D_ 1.Created a detailed document explaining the process that how we will govern the status of data readiness for AI use cases.[AI Foundation Building Check List.docx|https://cpkcrail.sharepoint.com/:w:/t/3_22025InformationServices/EZ5m8UgIkmVAv4gofW3JW7sBMaDKiz8JMPDrO_CssrQgQQ?e=vtELVH]_x000D_ _x000D_ 2.Created a checklist divided into 6 major sections and 35 subpoints to validate the alignment of the data platform for AI use cases.[AI Foundation Building Check List.ods|https://cpkcrail.sharepoint.com/:x:/t/3_22025InformationServices/ESTh5YZeE0BOsjyPg2PXbkUBbSY0Bay0nLIfFyCp6f-PKw?e=wswYGk]_x000D_ _x000D_ ;;; | CK19: 09/Dec/25 11:07 AM;woo0234;feedback required for [~aro0027] ;;;
A20: =VLOOKUP(AK20,members!$A:$C,3,FALSE) -> Celebal | B20: =VLOOKUP(AK20,members!$A:$C,2,FALSE) -> Jatin | C20: =X20 -> RPD-74 | D20: =AB20 -> In Progress | E20: =AU20 -> 46052 | F20: =W20 -> AI - Foundation building | G20: =AX20 -> building and monitoring foundation of AI platform for Rail 360 led by [~aro0027] | W20: AI - Foundation building | X20: RPD-74 | Y20: 190029 | AA20: Task | AB20: In Progress | AC20: RPD | AD20: Rail360 Product Development | AE20: software | AF20: las0044 | AI20: 3-High | AK20: aro0027 | AL20: woo0234 | AM20: woo0234 | AN20: 45996.492 | AO20: 46000.463 | AP20: 46001.015 | AU20: 46052 | AV20: 0 | AW20: Rail360 | AX20: building and monitoring foundation of AI platform for Rail 360 led by [~aro0027] | AY20: aro0027 | AZ20: woo0234 | CB20: 1|i0i59o: | CJ20: 09/Dec/25 9:14 AM;aro0027;I have created the AI Foundation Checklist for Rail 360's_x000D_ _x000D_ 1.Created a detailed document explaining the process that how we will govern the status of data readiness for AI use cases.[AI Foundation Building Check List.docx|https://cpkcrail.sharepoint.com/:w:/t/3_22025InformationServices/EZ5m8UgIkmVAv4gofW3JW7sBMaDKiz8JMPDrO_CssrQgQQ?e=vtELVH]_x000D_ _x000D_ 2.Created a checklist divided into 6 major sections and 35 subpoints to validate the alignment of the data platform for AI use cases.[AI Foundation Building Check List.ods|https://cpkcrail.sharepoint.com/:x:/t/3_22025InformationServices/ESTh5YZeE0BOsjyPg2PXbkUBbSY0Bay0nLIfFyCp6f-PKw?e=wswYGk];;;
A21: =VLOOKUP(AK21,members!$A:$C,3,FALSE) -> Squadron | B21: =VLOOKUP(AK21,members!$A:$C,2,FALSE) -> Harshil Patel | C21: =X21 -> RPD-77 | D21: =AB21 -> In Progress | E21: =AU21 -> 45999 | F21: =W21 -> ER diagram review | G21: =AX21 -> [~pat0606] [~tha0073] to complete review of ER diagram files | W21: ER diagram review | X21: RPD-77 | Y21: 190160 | Z21: 189315 | AA21: Sub-task | AB21: In Progress | AC21: RPD | AD21: Rail360 Product Development | AE21: software | AF21: las0044 | AI21: 3-High | AK21: pat0606 | AL21: woo0234 | AM21: woo0234 | AN21: 45999.469 | AO21: 46001.47 | AP21: 45999.482 | AU21: 45999 | AV21: 0 | AW21: Rail360 | AX21: [~pat0606] [~tha0073] to complete review of ER diagram files | AY21: dan0243 | AZ21: woo0234 | CB21: 1|i0i62s: | CJ21: 09/Dec/25 10:21 AM;dan0243;9/12 - we started deep dive into the doc shared by Vishu Priya we are doing Initial analysis of the existing system based on this we have identify two approaches 1. Dynamic table 2. Stored Proc. ;;; | CK21: 10/Dec/25 10:23 AM;dan0243;we would like to get the 4 queries in text form.[~cvps10] ;;; | CL21: 10/Dec/25 11:15 AM;woo0234;is being reviewed by Squadron team and architect;;; | CM21: 10/Dec/25 11:17 AM;woo0234;[~moh0106] has documents that depicts individual query for each table associated with the data flow for [~pat0606] and squadron team.;;;
A22: =VLOOKUP(AK22,members!$A:$C,3,FALSE) -> QE | B22: =VLOOKUP(AK22,members!$A:$C,2,FALSE) -> VishnuB | C22: =X22 -> RPD-80 | D22: =AB22 -> To Do | E22: =AU22 -> 46002 | F22: =W22 -> MDM entity testing - DIM commodity DIM customer DIM equipment tables. | G22: =AX22 -> [~bor0475] and [~sid0070] to initiate and take on... checking and automating tables related to DIM commodity DIM customer DIM equipment tables._x000D_ _x000D_ ensure [~seh0018] and [~ric0230] are involved and aligned | W22: MDM entity testing - DIM commodity DIM customer DIM equipment tables. | X22: RPD-80 | Y22: 190167 | AA22: Task | AB22: To Do | AC22: RPD | AD22: Rail360 Product Development | AE22: software | AF22: las0044 | AI22: 3-High | AK22: bor0475 | AL22: woo0234 | AM22: woo0234 | AN22: 45999.481 | AO22: 46002.452 | AP22: 45999.481 | AU22: 46002 | AV22: 0 | AW22: Rail360 | AX22: [~bor0475] and [~sid0070] to initiate and take on... checking and automating tables related to DIM commodity DIM customer DIM equipment tables._x000D_ _x000D_ ensure [~seh0018] and [~ric0230] are involved and aligned | AY22: bor0475 | AZ22: woo0234 | BM22: RPD-83 | BN22: 10/Dec/25 10:45 AM;bor0475;DIM_CUSTOMER -QA Findings.docx;https://jira.cpr.ca/secure/attachment/166191/DIM_CUSTOMER+-QA+Findings.docx | CB22: 1|i0i63w: | CJ22: 09/Dec/25 10:45 AM;bor0475;Testing/Automation started with DIM_CUSTOMER, will be targeting by 12/10/2025. ;;; | CK22: 10/Dec/25 10:46 AM;bor0475;Performed testing on the DIM_COMMODITY and communicated the findings to [~seh0018] _x000D_ _x000D_ [^DIM_CUSTOMER -QA Findings.docx];;; | CL22: 11/Dec/25 10:51 AM;bor0475;Started testing with DIM_COMMODITY.;;;
A23: =VLOOKUP(AK23,members!$A:$C,3,FALSE) -> QE | B23: =VLOOKUP(AK23,members!$A:$C,2,FALSE) -> VishnuB | C23: =X23 -> RPD-5 | D23: =AB23 -> In Progress | E23: =AU23 -> 46002 | F23: =W23 -> Test Planning Phase 2 (P415) - Conversion of requirement into Task Cases from P140 | G23: =AX23 -> Test Planning Phase 2 - Conversion of requirement into Task Cases from P140 requirement document_x000D_ (e.g. SADB transformation into Snowflake loading -> what transformation we do -> multiple subtask and testing cases to be followed)_x000D_ complete test plan with access to AWS and Cloud platforms | W23: Test Planning Phase 2 (P415) - Conversion of requirement into Task Cases from P140 | X23: RPD-5 | Y23: 186078 | AA23: Task | AB23: In Progress | AC23: RPD | AD23: Rail360 Product Development | AE23: software | AF23: las0044 | AI23: 3-High | AK23: bor0475 | AL23: woo0234 | AM23: woo0234 | AN23: 45951.578 | AO23: 46002.453 | AP23: 45999.479 | AU23: 46002 | AV23: 0 | AW23: Rail360 | AX23: Test Planning Phase 2 - Conversion of requirement into Task Cases from P140 requirement document_x000D_ (e.g. SADB transformation into Snowflake loading -> what transformation we do -> multiple subtask and testing cases to be followed)_x000D_ complete test plan with access to AWS and Cloud platforms | AY23: bor0475 | AZ23: cvps10 | BA23: sau0093 | BB23: sid0070 | BC23: woo0234 | CB23: 1|i0hj2k: | CJ23: 27/Oct/25 11:41 AM;woo0234;require a high-level solution from source to bronze (partially defined) and bronze to siliver (not started) and silver to gold (gold is defined but not the data pipeline)_x000D_ _x000D_ this requires update from [~kvxg11], [~cvps10] supported by [~sin0404] and [~sau0093] _x000D_ _x000D_ ;;; | CK23: 19/Nov/25 11:20 AM;cvps10;Dependent on P220 and P219;;; | CL23: 26/Nov/25 11:23 AM;sau0093;Waiting for P220.;;; | CM23: 02/Dec/25 11:10 AM;sid0070;Development can be started on current data in P220;;; | CN23: 03/Dec/25 11:03 AM;cvps10;Initial draft started;;; | CO23: 04/Dec/25 11:15 AM;bor0475;I started drafting P415 and targeting by Dec 8th , after I'll send to Automation/Performance teams for updates. Thanks!;;; | CP23: 10/Dec/25 10:41 AM;bor0475;I have updated Initial test plan and Automation updates are in progress.;;; | CQ23: 10/Dec/25 11:29 AM;woo0234;MDM - dim equipment table mapping document is missing to progress as per [~bor0475] . discussion needed with MDM team.;;; | CR23: 11/Dec/25 10:53 AM;bor0475;Automation updates have been incorporated with the test plan. I will share them for review today.;;;
A24: =VLOOKUP(AK24,members!$A:$C,3,FALSE) -> Architect | B24: =VLOOKUP(AK24,members!$A:$C,2,FALSE) -> David | C24: =X24 -> RPD-30 | D24: =AB24 -> Done | E24: =AU24 -> 45995 | F24: =W24 -> P310 LogicGate System Security Documentation (solution architect) | G24: =AX24 -> [~ngu0018] could you review and update proper ETA? this is part of required docu for stage gate purposes. | W24: P310 LogicGate System Security Documentation (solution architect) | X24: RPD-30 | Y24: 186290 | AA24: Task | AB24: Done | AC24: RPD | AD24: Rail360 Product Development | AE24: software | AF24: las0044 | AI24: 3-High | AJ24: Done | AK24: ngu0018 | AL24: woo0234 | AM24: woo0234 | AN24: 45954.503 | AO24: 46001.435 | AP24: 45999.46 | AQ24: 46001.435 | AU24: 45995 | AV24: 0 | AW24: Rail360 | AX24: [~ngu0018] could you review and update proper ETA? this is part of required docu for stage gate purposes. | AY24: ana0017 | AZ24: cvps10 | BA24: ngu0018 | BB24: sid0070 | BC24: woo0234 | BN24: 04/Dec/25 11:04 PM;ngu0018;LogicGate P310 - Rail 360 SG2.pdf;https://jira.cpr.ca/secure/attachment/165818/LogicGate+P310+-+Rail+360+SG2.pdf | BO24: 10/Dec/25 10:23 AM;ngu0018;LogicGate P310 - Rail 360 SG2-1.pdf;https://jira.cpr.ca/secure/attachment/166183/LogicGate+P310+-+Rail+360+SG2-1.pdf | CB24: 1|i0hkc4: | CJ24: 27/Oct/25 11:14 AM;woo0234;[~ngu0018] can you share estimated timeline/ effort for this document for us?_x000D_ _x000D_ ;;; | CK24: 04/Nov/25 9:42 AM;ngu0018;P310 is data recorded into LogicGate application for Enterprise Security to review the proposed solution for potential risk areas. This is done when the P219 has been reviewed and approved by EA, as the same data from P219 is transferred into LogicGate for ES. My target date to have the P219 completed, reviewed and approved by Nov 14th, provided that any/all outstanding questions regarding Snowflake and integration details have been answered. ;;; | CL24: 12/Nov/25 10:38 AM;ana0017;Will have it Complete. Next week after P219 Completion.;;; | CM24: 02/Dec/25 11:11 AM;sid0070;P219 is updated. can be used for this task;;; | CN24: 03/Dec/25 11:04 AM;cvps10;[~ngu0018] any progress on this?;;; | CO24: 03/Dec/25 11:27 AM;ngu0018;I will have the LogicGate record submitted today since we have decided to use IDMC and no longer waiting for a decision on Openflow for this phase of the project. ;;; | CP24: 04/Dec/25 7:18 PM;ngu0018;LogicGate P310 submitted for ES review and assessment. Assignee from ES is Bayo Oladele. Will provide update once ES assessment is complete.;;; | CQ24: 04/Dec/25 11:06 PM;ngu0018;ES Assessment completed with no risks identified. can proceed with SG2. ;;; | CR24: 10/Dec/25 10:24 AM;ngu0018;LogicGate P310 has been assessed by Enterprise Security and no risks identified. The project can proceed with PMO SG2 when ready. ;;;
A25: =VLOOKUP(AK25,members!$A:$C,3,FALSE) -> ETL | B25: =VLOOKUP(AK25,members!$A:$C,2,FALSE) -> Naveen | C25: =X25 -> RPD-54 | D25: =AB25 -> Done | E25: =AU25 -> 45988 | F25: =W25 -> Base Table - Setting Secure Agent and Testing jobs | G25: =AX25 -> once rpd-53 decision is made by architect._x000D_ _x000D_ start setting secure agent and testing jobs._x000D_ _x000D_ _x000D_ _x000D_ start today 11/20 for EXISTING JOBS._x000D_ _x000D_ _x000D_ _x000D_ if we go with openflow, there are different jobs to be followed. | W25: Base Table - Setting Secure Agent and Testing jobs | X25: RPD-54 | Y25: 188632 | Z25: 188628 | AA25: Sub-task | AB25: Done | AC25: RPD | AD25: Rail360 Product Development | AE25: software | AF25: las0044 | AI25: 3-High | AJ25: Done | AK25: knxn12 | AL25: woo0234 | AM25: woo0234 | AN25: 45981.477 | AO25: 45992.47 | AP25: 45992.47 | AQ25: 45992.47 | AU25: 45988 | AV25: 0 | AW25: Rail360 | AX25: once rpd-53 decision is made by architect._x000D_ _x000D_ start setting secure agent and testing jobs._x000D_ _x000D_ _x000D_ _x000D_ start today 11/20 for EXISTING JOBS._x000D_ _x000D_ _x000D_ _x000D_ if we go with openflow, there are different jobs to be followed. | AY25: woo0234 | CB25: 1|i0hxzw:
A26: =VLOOKUP(AK26,members!$A:$C,3,FALSE) -> ETL | B26: =VLOOKUP(AK26,members!$A:$C,2,FALSE) -> Naveen | C26: =X26 -> RPD-58 | D26: =AB26 -> In Progress | E26: =AU26 -> 45989 | F26: =W26 -> Create Informatica Secure Agent account for Squadron | G26: =AX26 -> meantime, start working via existing secure agent DEV | W26: Create Informatica Secure Agent account for Squadron | X26: RPD-58 | Y26: 188654 | AA26: Task | AB26: In Progress | AC26: RPD | AD26: Rail360 Product Development | AE26: software | AF26: las0044 | AI26: 3-High | AK26: knxn12 | AL26: woo0234 | AM26: woo0234 | AN26: 45981.558 | AO26: 45993.486 | AP26: 45992.469 | AU26: 45989 | AV26: 0 | AX26: meantime, start working via existing secure agent DEV | AY26: cvps10 | AZ26: woo0234 | CB26: 1|i0hxz4: | CJ26: 02/Dec/25 11:39 AM;cvps10;For now, existing secure agent is used. Naveen working on creating new secure agent. Dependent on multiple teams - might take 2 weeks;;;
A27: =VLOOKUP(AK27,members!$A:$C,3,FALSE) -> ETL | B27: =VLOOKUP(AK27,members!$A:$C,2,FALSE) -> Naveen | C27: =X27 -> RPD-59 | D27: =AB27 -> Done | E27: =AU27 -> 45981 | F27: =W27 -> Schema Testing (SADB) using existing module | G27: =AX27 -> [~ngu0018] asked ETL team to test connection for SADB by creating jobs. [~sin0404] [~knxn12] to follow. | W27: Schema Testing (SADB) using existing module | X27: RPD-59 | Y27: 188656 | Z27: 188628 | AA27: Sub-task | AB27: Done | AC27: RPD | AD27: Rail360 Product Development | AE27: software | AF27: las0044 | AI27: 3-High | AJ27: Done | AK27: knxn12 | AL27: woo0234 | AM27: woo0234 | AN27: 45981.564 | AO27: 45988.47 | AP27: 45988.47 | AQ27: 45988.47 | AU27: 45981 | AV27: 0 | AW27: Rail360 | AX27: [~ngu0018] asked ETL team to test connection for SADB by creating jobs. [~sin0404] [~knxn12] to follow. | AY27: sau0093 | AZ27: woo0234 | CB27: 1|i0hy50: | CJ27: 26/Nov/25 11:12 AM;sau0093;Openflow steup is still pending. ;;;
A28: =VLOOKUP(AK28,members!$A:$C,3,FALSE) -> Squadron | B28: =VLOOKUP(AK28,members!$A:$C,2,FALSE) -> Babu | C28: =X28 -> RPD-66 | D28: =AB28 -> To Do | E28: 46010 | F28: =W28 -> SnowFlake ETL Plan - Silver to Gold solution to provide - document / email needed | G28: =AX28 -> Document that_x000D_ _x000D_ includes methodologies out of below example options._x000D_ _x000D_ include data models for Silver Layers_x000D_ _x000D_ _x000D_ _x000D_ 1) DBT_x000D_ _x000D_ 2) Store Procedures_x000D_ _x000D_ 3) Snow Park | W28: SnowFlake ETL Plan - Silver to Gold solution to provide - document / email needed | X28: RPD-66 | Y28: 189014 | AA28: Task | AB28: To Do | AC28: RPD | AD28: Rail360 Product Development | AE28: software | AF28: las0044 | AI28: 3-High | AK28: tha0073 | AL28: woo0234 | AM28: woo0234 | AN28: 45988.47 | AO28: 46001.431 | AP28: 45988.47 | AU28: 45994 | AV28: 0 | AW28: Rail360 | AX28: Document that_x000D_ _x000D_ includes methodologies out of below example options._x000D_ _x000D_ include data models for Silver Layers_x000D_ _x000D_ _x000D_ _x000D_ 1) DBT_x000D_ _x000D_ 2) Store Procedures_x000D_ _x000D_ 3) Snow Park | AY28: dan0243 | AZ28: woo0234 | BN28: 10/Dec/25 10:17 AM;dan0243;Snowflake Native Capabilities_v2.docx;https://jira.cpr.ca/secure/attachment/166182/Snowflake+Native+Capabilities_v2.docx | CB28: 1|i0i06c: | CJ28: 09/Dec/25 10:10 AM;dan0243;9/12 - Since it a dependent on data modeling document;;; | CK28: 10/Dec/25 10:21 AM;dan0243;Once we decide the silver layer approach and bring up the data from all sources. we will then finalize the silver to gold. but for the better understanding i have attached the document ;;;
A29: =VLOOKUP(AK29,members!$A:$C,3,FALSE) -> BDA | B29: =VLOOKUP(AK29,members!$A:$C,2,FALSE) -> VPS | C29: =X29 -> RPD-64 | D29: =AB29 -> Done | E29: =AU29 -> 45993 | F29: =W29 -> allocate to celebal team with KT by 12/2 Tuesday | G29: =AX29 -> [~cvps10] to KT to Celebal team [~moh0106] and [~bab0060] / [~aro0027] | W29: allocate to celebal team with KT by 12/2 Tuesday | X29: RPD-64 | Y29: 188862 | Z29: 188014 | AA29: Sub-task | AB29: Done | AC29: RPD | AD29: Rail360 Product Development | AE29: software | AF29: las0044 | AI29: 3-High | AJ29: Done | AK29: cvps10 | AL29: woo0234 | AM29: woo0234 | AN29: 45986.469 | AO29: 45993.484 | AP29: 45986.469 | AQ29: 45993.484 | AU29: 45993 | AV29: 0 | AW29: Rail360 | AX29: [~cvps10] to KT to Celebal team [~moh0106] and [~bab0060] / [~aro0027] | AY29: cvps10 | AZ29: woo0234 | CB29: 1|i0hzck: | CJ29: 02/Dec/25 11:37 AM;cvps10;KT completed with the help of documents and recordings by Sangtae and team for Rail 360;;;
